Исключения - ошибки работы коды. И возникает оно только в момент выполнения.Но есть
ошибки которые срабатывают и до выполнения нужной строчки, например неверный отступ

print('hello')
 print('hello1') # не даст запустить код так как лишний пробел в начале

Что же делать с иключениям из разряда ValueError и тд
Если мы знаем что в какой-то части кода может возникнуть исключение
то его можно отловить через try except

print('hello')
print('hello1')

try:
    int('hello') # попробовали преобразовать строку в int
except ValueError: # если ошибка ValueError выполняем код ниже
    print('Ошибка преобразования')

print('hello2')
print('hello3')

# Вывод
hello
hello1
Ошибка преобразования
hello2
hello3
#

Готово! Ошибка отловлена и обработана

Также если надо можно самому вызвать исключение с помощью слова raise

raise ValueError('Ошибка')














