
После блока try мы можем отлавливать сколько угодно исключений

try:
    int('123456')
    a + b
except ValueError:
    print('error ValueError')
except ZeroDivisionError:
    print('error ZeroDivisionError')
except NameError:
    print('error NameError')

Все ошибки будут отловлены

Если мы допустим не зная какая будет ошибка, а просто хотим вывести что она есть
просто пишем
try:
	a + b
except:
	print('Ошибка')

# Ошибка

Или просто использовать иключение except Exception(оно почти в самом верху иерархии исключений и 
включает в себя почти всё)

Также есть такой блок как finally

try:
    a + b
except:
    print('Ошибка')
finally:
    print('Закончили')

И этот блок отработает в любом случае, сработает исключение или нет будет отработан код в блоке
finally
# Вывод
Ошибка
Закончили
#

Мы можем вообще не обрабатывать исключения, а сразу делать finally

f = open('111.txt')
try:
    f + 3
finally:
    print('end')
    f.close()

Это помогает например при работе с файлами, чтоб всегда не забывать закрывать файл

Также можно передавать несколько исключений в except в виде кортежа и использовать else


try:
    1 / 5
except (KeyError, IndexError):
    print('Error')
else:
    print('good')
finally:
    print('end')

# Вывод
good
end
#

else Отрабатывает только тогда когда исключений не было