Во время написания except каждому исключению можно дать псевдоним

try:
    1/0
except ZeroDivisionError as err:
    print('ZeroDivisionError')

Мы теперь можем эту переменную как-то использовать, ну например

try:
    1/0
except ZeroDivisionError as err:
    print('ZeroDivisionError')
    print(f'Ошибка {err} {repr(err)}')

# Вывод
ZeroDivisionError
Ошибка division by zero ZeroDivisionError('division by zero')
#



